Workbook
Name dr: [1]DCF!$E$18
Name dr: [1]DCF!$E$18
Name dr: DCF!$E$18
Name tg: [1]DCF!$E$19
Name tg: [1]DCF!$E$19
Name tg: DCF!$E$19
Name tgr: [2]DCF!$E$19
Name wacc: [2]DCF!$E$18

Sheet Cover
A1: x`
B2: Cover
A4: x | B4: Agenda
B5: 1. Palantir Situation Overview
B6: 2. Trading Comps
B7: 3. Street-Based DCF
B8: 4. Calculating Diluted Share Count
B9: 5. WACC, Mid-Year Convention
B10: 6. Price discussion
A12: x | B12: Situation Overview
B13: The Bull Case
B14: 1. Leader in AI, offering Gotham, Foundry, and the Artificial Intelligence Platform (AIP)
B15: 2. Crushed the most recent quarter (Q3 2024), reporting a 30% year-over-year revenue increase, marking six consecutive quarters of accelerating growth
B16: 3. Strategic partnerships with the government create a strong moat for the company
B18: The Bear Case
B19: 1. High valuation means the stock is priced for perfection; increasing short activity
B20: 2. Over reliance on government relationships and top customers mean that any churn could materially hurt revenue and momentum
B21: 3. Extremely competitive market with lots of execution risk particularly in the commerical space

Sheet DCF
A1: DCF
A3: Ticker | B3: PLTR | D3: Current Stock Price | G3: 170.96
A4: Date | B4: 46038 | D4: Implied Share Price | G4: =P82 -> 46.908214
A5: Year End | B5: 46387 | D5: Upside / (Downside) | G5: =G4/G3-1 -> -0.72561878
A7: Assumptions
A9: Switches | F9: Conservative | K9: Base | P9: Optimistic
A10: Assumptions | F10: Assumptions | H10: Year | I10: Metric | K10: Assumptions | M10: Year | N10: Metric | P10: Assumptions | R10: Year | S10: Metric
A11: Revenue | D11: 3 | F11: Revenue | H11: 2026 | I11: 0.75 | P11: Revenue | R11: 2026 | S11: 1
A12: EBIT | D12: 3 | F12: Revenue | H12: '27 - '30 | I12: 0.7 | K12: Revenue | M12: '27 - '30 | N12: 0.8 | P12: Revenue | R12: '27 - '30 | S12: 0.9
A13: WACC | D13: 3 | F13: EBIT | H13: 2030 | I13: 0.35 | K13: EBIT | M13: 2030 | N13: 0.4 | P13: EBIT | R13: 2030 | S13: 0.48
A14: TGR | D14: 3
A16: Valuation
A17: WACC | D17: =CHOOSE(D13,I17,N17,S17) -> 0.11 | F17: WACC | I17: 0.1323 | K17: WACC | N17: 0.1271 | P17: WACC | S17: 0.11
A18: TGR | D18: =CHOOSE(D14,I18,N18,S18) -> 0.03 | F18: TGR | I18: 0.02 | K18: TGR | N18: 0.025 | P18: TGR | S18: 0.03
A20: Income Statement (12/31, USD M) | D20: 2018 | E20: =D20+1 -> 2019 | F20: =E20+1 -> 2020 | G20: =F20+1 -> 2021 | H20: =G20+1 -> 2022 | I20: =H20+1 -> 2023 | J20: =I20+1 -> 2024 | K20: =J20+1 -> 2025 | L20: =K20+1 -> 2026 | M20: =L20+1 -> 2027
A21: Revenue | D21: 595.409 | E21: 742.555 | F21: 1092.673 | G21: 1541.889 | H21: 1905.871 | I21: 2225.012 | J21: 2865.507 | K21: 4405.79 | L21: 6292.71 | M21: 8734.79
A22: % growth | D22: -- | E22: =E21/D21-1 -> 0.24713432 | F22: =F21/E21-1 -> 0.47150447 | G22: =G21/F21-1 -> 0.41111659 | H22: =H21/G21-1 -> 0.23606239 | I22: =I21/H21-1 -> 0.16745152 | J22: =J21/I21-1 -> 0.28786137 | K22: =K21/J21-1 -> 0.53752547 | L22: =L21/K21-1 -> 0.42828187 | M22: =M21/L21-1 -> 0.38808081
A24: EBIT | D24: -623.44 | E24: -576.444 | F24: -1173.679 | G24: -411.046 | H24: -161.201 | I24: 119.966 | J24: 310.403 | K24: 2145.87 | L24: 3133.46 | M24: 4419.98
A25: % of sales | D25: =D24/D21 -> -1.0470786 | E25: =E24/E21 -> -0.77629805 | F25: =F24/F21 -> -1.0741356 | G25: =G24/G21 -> -0.26658599 | H25: =H24/H21 -> -0.084581275 | I25: =I24/I21 -> 0.053917013 | J25: =J24/J21 -> 0.10832394 | K25: =K24/K21 -> 0.4870568 | ... M25: =M24/M21 -> 0.50602018 | N25: Non-Gaap
A27: Taxes | D27: 9.102 | E27: 12.375 | F27: -12.636 | G27: 31.885 | H27: 10.067 | I27: 19.716 | J27: 21.255
A28: Tax rate | D28: =D27/'IS - Annual'!I31 -> -0.015942549 | E28: =E27/'IS - Annual'!H31 -> -0.02181497 | F28: =F27/'IS - Annual'!G31 -> 0.010717312 | G28: =G27/'IS - Annual'!F31 -> -0.06527204 | H28: =H27/'IS - Annual'!E31 -> -0.027884341 | I28: =I27/'IS - Annual'!D31 -> 0.083157944 | J28: =J27/'IS - Annual'!C31 -> 0.043450885
A30: Cash Flow Items (12/31, USD M) | D30: 2018 | E30: =D30+1 -> 2019 | F30: =E30+1 -> 2020 | G30: =F30+1 -> 2021 | H30: =G30+1 -> 2022 | I30: =H30+1 -> 2023 | J30: =I30+1 -> 2024 | K30: =J30+1 -> 2025 | L30: =K30+1 -> 2026 | M30: =L30+1 -> 2027
A31: D&A | D31: 13.91 | E31: 12.255 | F31: 13.871 | G31: 14.897 | H31: 22.522 | I31: 33.354 | J31: 31.587
A32: % of sales | D32: =D31/D$21 -> 0.023362092 | E32: =E31/E$21 -> 0.016503828 | F32: =F31/F$21 -> 0.012694557 | G32: =G31/G$21 -> 0.0096615256 | H32: =H31/H$21 -> 0.011817169 | I32: =I31/I$21 -> 0.014990481 | J32: =J31/J$21 -> 0.01102318
A34: CapEx | D34: 15.404 | E34: 13.096 | F34: 12.236 | G34: 12.637 | H34: 40.027 | I34: 15.114 | J34: 12.634 | K34: 29.9612 | L34: 40.6154 | M34: 49.0852
A35: % of sales | D35: =D34/D$21 -> 0.025871292 | E35: =E34/E$21 -> 0.017636404 | F35: =F34/F$21 -> 0.011198227 | G35: =G34/G$21 -> 0.008195791 | H35: =H34/H$21 -> 0.021001946 | I35: =I34/I$21 -> 0.0067927724 | J35: =J34/J$21 -> 0.0044089929
A37: Change in NWC | D37: 302.575 | E37: 134.027 | F37: -454.119 | G37: -92.052 | H37: -267.103 | I37: 6.236 | J37: -70.097
A38: % of sales | D38: =D37/D$21 -> 0.50818009 | E38: =E37/E$21 -> 0.18049437 | F38: =F37/F$21 -> -0.41560375 | G38: =G37/G$21 -> -0.059700796 | H38: =H37/H$21 -> -0.14014747 | I38: =I37/I$21 -> 0.0028026815 | J38: =J37/J$21 -> -0.024462338
A39: % of change in sales | D39: -- | E39: =E37/(E21-D21) -> 0.91084365 | F39: =F37/(F21-E21) -> -1.2970456 | G39: =G37/(G21-F21) -> -0.20491701 | H39: =H37/(H21-G21) -> -0.73383574 | I39: =I37/(I21-H21) -> 0.019539953 | J39: =J37/(J21-I21) -> -0.10944192
K40: 0.25 | L40: 1 | M40: =L40+1 -> 2 | N40: =M40+1 -> 3 | O40: =N40+1 -> 4 | P40: =O40+1 -> 5
A41: DCF (12/31, USD M) | D41: 2018 | E41: =D41+1 -> 2019 | F41: =E41+1 -> 2020 | G41: =F41+1 -> 2021 | H41: =G41+1 -> 2022 | I41: =H41+1 -> 2023 | J41: =I41+1 -> 2024 | K41: =J41+1 -> 2025 | L41: =K41+1 -> 2026 | ... P41: =O41+1 -> 2030
A42: Revenue | D42: =D21 -> 595.409 | E42: =E21 -> 742.555 | F42: =F21 -> 1092.673 | G42: =G21 -> 1541.889 | H42: =H21 -> 1905.871 | I42: =I21 -> 2225.012 | J42: =J21 -> 2865.507 | K42: =J42*(1+K43) -> 4463.1001 | L42: =K42*(1+L43) -> 6951.3921 | M42: =L42*(1+M43) -> 10439.413 | N42: =M42*(1+N43) -> 15153.806 | O42: =N42*(1+O43) -> 21312.859 | P42: =O42*(1+P43) -> 29108.942
A43: % growth | D43: =D22 -> -- | E43: =E22 -> 0.24713432 | F43: =F22 -> 0.47150447 | G43: =G22 -> 0.41111659 | H43: =H22 -> 0.23606239 | I43: =I22 -> 0.16745152 | J43: =J22 -> 0.28786137 | K43: =OFFSET(K43,$D$11,0) -> 0.55752547 | L43: =OFFSET(L43,$D$11,0) -> 0.55752547 | M43: =OFFSET(M43,$D$11,0) -> 0.50177292 | N43: =OFFSET(N43,$D$11,0) -> 0.45159563 | O43: =OFFSET(O43,$D$11,0) -> 0.40643607 | P43: =OFFSET(P43,$D$11,0) -> 0.36579246
A44: Conservative | K44: =K22 - 2% -> 0.51752547 | L44: =K44*$I$11 -> 0.3881441 | M44: =L44*$I$12 -> 0.27170087 | N44: =M44*$I$12 -> 0.19019061 | O44: =N44*$I$12 -> 0.13313343 | P44: =O44*$I$12 -> 0.093193399
A45: Base (Street) | K45: =K22 -> 0.53752547 | L45: =L22 -> 0.42828187 | M45: =L45*$N$12 -> 0.3426255 | N45: =M45*$N$12 -> 0.2741004 | O45: =N45*$N$12 -> 0.21928032 | P45: =O45*$N$12 -> 0.17542426
A46: Optimistic | K46: =K22 + 2% -> 0.55752547 | L46: =K46*S11 -> 0.55752547 | M46: =L46*$S$12 -> 0.50177292 | N46: =M46*$S$12 -> 0.45159563 | O46: =N46*$S$12 -> 0.40643607 | P46: =O46*$S$12 -> 0.36579246
A48: EBIT | D48: =D24 -> -623.44 | E48: =E24 -> -576.444 | F48: =F24 -> -1173.679 | G48: =G24 -> -411.046 | H48: =H24 -> -161.201 | I48: =I24 -> 119.966 | J48: =J24 -> 310.403 | K48: =K49*K42 -> 2410.0741 | L48: =L49*L42 -> 3670.3351 | M48: =M49*M42 -> 5386.7369 | N48: =N49*N42 -> 7637.518 | O48: =O49*O42 -> 10485.927 | P48: =P49*P42 -> 13972.292
A49: % of sales | D49: =D25 -> -1.0470786 | E49: =E25 -> -0.77629805 | F49: =F25 -> -1.0741356 | G49: =G25 -> -0.26658599 | H49: =H25 -> -0.084581275 | I49: =I25 -> 0.053917013 | J49: =J25 -> 0.10832394 | K49: =OFFSET(K49,$D$12,0) -> 0.54 | L49: =OFFSET(L49,$D$12,0) -> 0.528 | M49: =OFFSET(M49,$D$12,0) -> 0.516 | N49: =OFFSET(N49,$D$12,0) -> 0.504 | O49: =OFFSET(O49,$D$12,0) -> 0.492 | P49: =OFFSET(P49,$D$12,0) -> 0.48
A50: Conservative | K50: =K51 -1% -> 0.3 | L50: =K50+(($P50-$K50)/($P$41-$K$41)) -> 0.31 | M50: =L50+(($P50-$K50)/($P$41-$K$41)) -> 0.32 | N50: =M50+(($P50-$K50)/($P$41-$K$41)) -> 0.33 | O50: =N50+(($P50-$K50)/($P$41-$K$41)) -> 0.34 | P50: =I13 -> 0.35 | R50: Target EBIT | S50: Margin
A51: Base (Street) | K51: 0.31 | L51: =K51+(($P51-$K51)/($P$41-$K$41)) -> 0.328 | M51: =L51+(($P51-$K51)/($P$41-$K$41)) -> 0.346 | N51: =M51+(($P51-$K51)/($P$41-$K$41)) -> 0.364 | O51: =N51+(($P51-$K51)/($P$41-$K$41)) -> 0.382 | P51: =N13 -> 0.4
...

Sheet WACC
B2: WACC
B4: WACC = % of equity x cost of equity + % of debt x cost of debt x (1 - Tax Rate)
B5: Cost of equity = Risk free rate + Beta x Market Risk Premium
A7: x | B7: WACC
B8: Market Cap | F8: 458882 | G8: mil
B9: % of Equity | F9: =F8/$F$20 -> 1
B10: Cost of Equity | F10: =F11+F12*F13 -> 0.127124
B11: Risk Free Rate | F11: 0.04227
B12: Beta | F12: 2.03
B13: Market Risk Premium | F13: 0.0418
B15: Debt | F15: 0
B16: % of Debt | F16: =F15/$F$20 -> 0
B17: Cost of Debt | F17: 0
B18: Tax Rate | F18: =[1]DCF!K56 -> 0.14
B20: Total | F20: =F8+F15 -> 458882
A22: x | B22: WACC | F22: =F9*F10+(F16*F17*(1-F18)) -> 0.127124
B23: FS WACC | F23: 0.1323

Sheet Shares
B2: Diluted Share Count Calculation
A4: x | B4: Full Diluted Shares
B6: Current price | E6: 170.96
B7: Basic shares outstanding (latest filing) | E7: =(2284334012+98097326+1005000)/1000000 -> 2383.4363
B8: In-the-money exercisable options | E8: =E32 -> 165.21
B9: Total proceeds ($mm) | E9: =SUMPRODUCT(D21:D30,E21:E30) -> 2980.9692
B10: Total shares repurchased (mm) | E10: =E9/E6 -> 17.436647
B11: Net dilutive options | E11: =E8-E10 -> 147.77335
B13: RSUs | E13: 47.589
B14: PSUs | E14: 0.133
B16: Net diluted shares outstanding | E16: =E7+E11+E13+E14 -> 2578.9317
A18: x | B18: Options outstanding
C20: Outstanding | D20: Exercise price | E20: Dilutive Shares
B21: 1 | C21: 153.949 | D21: 9.92 | E21: =IF(D21<$E$6,C21) -> 153.949 | F21: Options
B22: =B21+1 -> 2 | C22: 11.261 | D22: 129.1 | E22: =IF(D22<$E$6,C22) -> 11.261 | F22: SARs
B23: =B22+1 -> 3 | E23: =IF(D23<$E$6,C23) -> 0
B24: =B23+1 -> 4 | E24: =IF(D24<$E$6,C24) -> 0
B25: =B24+1 -> 5 | E25: =IF(D25<$E$6,C25) -> 0
B26: =B25+1 -> 6 | E26: =IF(D26<$E$6,C26) -> 0
B27: =B26+1 -> 7 | E27: =IF(D27<$E$6,C27) -> 0
B28: =B27+1 -> 8 | E28: =IF(D28<$E$6,C28) -> 0
B29: =B28+1 -> 9 | E29: =IF(D29<$E$6,C29) -> 0
B30: =B29+1 -> 10 | E30: =IF(D30<$E$6,C30) -> 0
A32: x | B32: Total | E32: =SUM(E21:E30) -> 165.21

Sheet IS - Annual
A1: Palantir Technologies Inc. Class A (PLTR)
A2: $178.40
A5: Palantir Technologies Inc. Class A
A6: PLTR 69608A108 BN78DQ4 NASDAQ Common stock
A7: Source: FactSet Fundamentals
B8: SEP '25 | C8: DEC '24 | D8: DEC '23 | E8: DEC '22 | F8: DEC '21 | G8: DEC '20 | H8: DEC '19 | I8: DEC '18
B9: LTM
A10: Sales | B10: 3896.163 | C10: 2865.507 | D10: 2225.012 | E10: 1905.871 | F10: 1541.889 | G10: 1092.673 | H10: 742.555 | I10: 595.409
A11: Cost of Goods Sold (COGS) incl. D&A | B11: 747.744 | C11: 565.99 | D11: 431.105 | E11: 408.549 | F11: 339.404 | G11: 352.547 | H11: 242.373 | I11: 165.401
A12: COGS excluding D&A | B12: 721.611 | C12: 534.403 | D12: 397.751 | E12: 386.027 | F12: 324.507 | G12: 338.676 | H12: 230.173 | I12: 151.601
A13: Depreciation & Amortization Expense | B13: 26.133 | C13: 31.587 | D13: 33.354 | E13: 22.522 | F13: 14.897 | G13: 13.871 | H13: 12.2 | I13: 13.8
A14: Depreciation | B14: 21.287 | C14: 23.787 | D14: 33.354 | E14: 22.522 | F14: 14.897 | G14: 13.871 | H14: 12.2 | I14: 13.8
A15: Amortization of Intangibles | B15: 4.846 | C15: 7.8 | D15: 0 | E15: 0
A16: Gross Income | B16: 3148.419 | C16: 2299.517 | D16: 1793.907 | E16: 1497.322 | F16: 1202.485 | G16: 740.126 | H16: 500.182 | I16: 430.008
A17: SG&A Expense | B17: 2298.755 | C17: 1989.114 | D17: 1673.941 | E17: 1658.523 | F17: 1613.531 | G17: 1913.805 | H17: 1076.626 | I17: 1053.448
A18: Research & Development | B18: 585.625 | C18: 507.878 | D18: 404.624 | E18: 359.679 | F18: 387.487 | G18: 560.66 | H18: 305.563 | I18: 285.451
A19: Other SG&A | B19: 1713.13 | C19: 1481.236 | D19: 1269.317 | E19: 1298.844 | F19: 1226.044 | G19: 1353.145 | H19: 771.063 | I19: 767.997
A20: EBIT (Operating Income) | B20: 849.664 | C20: 310.403 | D20: 119.966 | E20: -161.201 | F20: -411.046 | G20: -1173.679 | H20: -576.444 | I20: -623.44
A21: Nonoperating Income - Net | B21: 258.759 | C21: 178.77 | D21: 125.095 | E21: -81.068 | F21: -73.808 | G21: 7.98 | H21: 12.237 | I21: 7.862
A22: Nonoperating Interest Income | B22: 221.185 | C22: 196.792 | D22: 132.572 | E22: 20.309 | F22: 1.607 | G22: 4.68 | H22: 15.09 | I22: 10.5
A23: Other Income (Expense) | B23: 37.574 | C23: -18.022 | D23: -7.477 | E23: -101.377 | F23: -75.415 | G23: 3.3 | H23: -2.853 | I23: -2.638
A24: Interest Expense | B24: 0 | C24: 0 | D24: 3.47 | E24: 4.058 | F24: 3.64 | G24: 14.139 | H24: 3.061 | I24: 3.44
A25: Gross Interest Expense | B25: 0 | C25: 0 | D25: 3.47 | E25: 4.058 | F25: 3.64 | G25: 14.139 | H25: 3.061 | I25: 3.44
A26: Unusual Expense - Net | B26: -8.1 | C26: 0 | D26: 4.5 | E26: 114.7 | F26: 0 | G26: -0.811 | H26: 0.003 | I26: -48.093
A27: Restructuring Expense | B27: 0 | C27: 0 | D27: 0 | E27: -44.3 | F27: 0 | G27: 0 | H27: 0 | I27: 0
A28: Unrealized Valuation Gain/Loss | B28: 8.1 | C28: 0 | D28: -4.5 | E28: -159 | G28: 0.811 | H28: -0.003 | I28: 48.093
A29: Investments | B29: 8.1 | C29: 0 | D29: -4.5 | E29: -159
A30: Hedges/Derivatives | G30: 0.811 | H30: -0.003 | I30: 48.093
A31: Pretax Income | B31: 1116.523 | C31: 489.173 | D31: 237.091 | E31: -361.027 | F31: -488.494 | G31: -1179.027 | H31: -567.271 | I31: -570.925
A32: Income Taxes | B32: 16.55 | C32: 21.255 | D32: 19.716 | E32: 10.067 | F32: 31.885 | G32: -12.636 | H32: 12.375 | I32: 9.102
A33: Income Taxes - Current Domestic | C33: 1.556 | D33: 2.333 | E33: 0.765 | F33: -0.088 | G33: 0.5 | H33: 0.139 | I33: 0.142
A34: Income Taxes - Current Foreign | C34: 20.265 | D34: 22.189 | E34: 9.476 | F34: -11.343 | G34: 7.249 | H34: 19.435 | I34: 15.945
A35: Income Taxes - Deferred Domestic | C35: 0 | D35: 0 | E35: 0 | F35: -0.111 | G35: 0 | H35: 0 | I35: 0
A36: Income Taxes - Deferred Foreign | C36: -0.566 | D36: -4.806 | E36: -0.174 | F36: 43.427 | G36: -20.385 | H36: -7.199 | I36: -6.985
A37: Other After Tax Adjustments | B37: 0 | C37: 0 | D37: 0 | E37: 0 | F37: 0 | G37: -5.483 | H37: -8.481 | I37: 0
A38: Consolidated Net Income | B38: 1099.973 | C38: 467.918 | D38: 217.375 | E38: -371.094 | F38: -520.379 | G38: -1171.874 | H38: -588.127 | I38: -580.027
A39: Minority Interest | B39: 4.607 | C39: 5.728 | D39: 7.55 | E39: 2.611 | F39: 0 | G39: 0 | H39: 0 | I39: 0
A40: Net Income | B40: 1095.366 | C40: 462.19 | D40: 209.825 | E40: -373.705 | F40: -520.379 | G40: -1171.874 | H40: -588.127 | I40: -580.027
A41: Preferred Dividends | B41: 0 | C41: 0 | D41: 0 | E41: 0 | F41: 0 | G41: 0 | H41: 0 | I41: 18.098
A42: Net Income available to Common | B42: 1095.366 | C42: 462.19 | D42: 209.825 | E42: -373.705 | F42: -520.379 | G42: -1171.874 | H42: -588.127 | I42: -598.125
...

Sheet CFS - Annual
A1: Palantir Technologies Inc. Class A (PLTR)
A2: $178.40
A5: Palantir Technologies Inc. Class A
A6: PLTR 69608A108 BN78DQ4 NASDAQ Common stock
A7: Source: FactSet Fundamentals
B8: SEP '25 | C8: DEC '24 | D8: DEC '23 | E8: DEC '22 | F8: DEC '21 | G8: DEC '20 | H8: DEC '19 | I8: DEC '18
B9: LTM
A10: Operating Activities
A11: Net Income / Starting Line | B11: 1099.973 | C11: 467.918 | D11: 217.375 | E11: -371.094 | F11: -520.379 | G11: -1166.391 | H11: -579.646 | I11: -580.027
A12: Depreciation, Depletion & Amortization | B12: 26.133 | C12: 31.587 | D12: 33.354 | E12: 22.522 | F12: 14.897 | G12: 13.871 | H12: 12.255 | I12: 13.91
A13: Depreciation and Depletion | B13: 21.287 | C13: 23.787 | D13: 33.354 | E13: 22.522 | F13: 14.897 | G13: 13.871 | H13: 12.255 | I13: 13.91
A14: Amortization of Intangible Assets | B14: 4.846 | C14: 7.8
A15: Deferred Taxes & Investment Tax Credit | B15: 0 | C15: 0 | D15: -4.806 | E15: -0.174 | F15: 43.316 | G15: 0 | H15: 0 | I15: 0
A16: Deferred Taxes | B16: 0 | C16: 0 | D16: -4.806 | E16: -0.174 | F16: 43.316 | G16: 0 | H16: 0 | I16: 0
A17: Other Funds | B17: 748.642 | C17: 724.457 | D17: 460.024 | E17: 839.586 | F17: 888.069 | G17: 1310.031 | H17: 268.149 | I17: 224.53
A18: Funds from Operations | B18: 1874.748 | C18: 1223.962 | D18: 705.947 | E18: 490.84 | F18: 425.903 | G18: 157.511 | H18: -299.242 | I18: -341.587
A19: Changes in Working Capital | B19: -57.243 | C19: -70.097 | D19: 6.236 | E19: -267.103 | F19: -92.052 | G19: -454.119 | H19: 134.027 | I19: 302.575
A20: Receivables | B20: -322.435 | C20: -211.157 | D20: -106.159 | E20: -77.519 | F20: -35.237 | G20: -108.476 | H20: -23.905 | I20: -10.483
A21: Accounts Payable | B21: 64.031 | C21: -18.841 | D21: -31.832 | E21: -29.859 | F21: 57.767 | G21: -34.681 | H21: 23.424 | I21: 10.968
A22: Other Accruals | C22: 115.634 | D22: 52.895 | E22: 5.527 | F22: 15.245 | G22: 38.505 | H22: 0.319 | I22: 25.103
A23: Other Assets/Liabilities | B23: 127.676 | C23: 44.267 | D23: 91.332 | E23: -165.252 | F23: -129.827 | G23: -349.467 | H23: 134.189 | I23: 276.987
A24: Net Operating Cash Flow | B24: 1817.505 | C24: 1153.865 | D24: 712.183 | E24: 223.737 | F24: 333.851 | G24: -296.608 | H24: -165.215 | I24: -39.012
A25: Investing Activities
A26: Capital Expenditures | B26: -23.716 | C26: -12.634 | D26: -15.114 | E26: -40.027 | F26: -12.627 | G26: -12.236 | H26: -13.096 | I26: -15.404
A27: Capital Expenditures (Fixed Assets) | B27: -23.716 | C27: -12.634 | D27: -15.114 | E27: -40.027 | F27: -12.627 | G27: -12.236 | H27: -13.096 | I27: -15.404
A28: Net Assets from Acquisitions | B28: 0 | C28: 0 | D28: 0 | E28: 66.708 | F28: 0 | G28: 0 | H28: 0 | I28: 0
A29: Sale of Fixed Assets & Businesses | B29: 0 | C29: 0 | D29: 0 | E29: 0 | F29: 0 | G29: 0.25 | H29: 0 | I29: 8.62
A30: Purchase/Sale of Investments | B30: -1086.271 | C30: -322.406 | D30: -2696.066 | E30: -72.181 | F30: -382.265 | G30: -2.934 | H30: -8.868 | I30: 0
A31: Purchase of Investments | B31: 8068.727 | C31: 5395.913 | D31: 5636.406 | E31: 124.5 | F31: 382.265 | G31: 2.934 | H31: 25.868 | I31: 0
A32: Sale/Maturity of Investments | B32: 6982.456 | C32: 5073.507 | D32: 2940.34 | E32: 52.319 | F32: 0 | G32: 0 | H32: 17 | I32: 0
A33: Other Funds | B33: -75.539 | C33: -5.615 | D33: 0 | E33: 0.073 | F33: -3.02 | G33: 0 | H33: 0 | I33: 0
A34: Other Uses | B34: -75.539 | C34: -5.615 | D34: 0 | E34: 0 | F34: -3.02 | G34: 0 | H34: 0 | I34: 0
A35: Other Sources | B35: 0 | C35: 0 | D35: 0 | E35: 0.073 | F35: 0 | G35: 0 | H35: 0 | I35: 0
A36: Net Investing Cash Flow | B36: -1185.526 | C36: -340.655 | D36: -2711.18 | E36: -45.427 | F36: -397.912 | G36: -14.92 | H36: -21.964 | I36: -6.784
A37: Financing Activities
A38: Change in Capital Stock | B38: 521.641 | C38: 681.2 | D38: 218.238 | E38: 86.089 | F38: 0 | G38: 1237.581 | H38: -68.678 | I38: 101.445
A39: Repurchase of Common & Preferred Stk. | B39: -74.387 | C39: -64.196 | D39: 0 | E39: 0 | F39: 0 | G39: -3.777 | H39: -193.075 | I39: -7.706
A40: Sale of Common & Preferred Stock | B40: 596.028 | C40: 745.396 | D40: 218.238 | E40: 86.089 | F40: 0 | G40: 1241.358 | H40: 124.397 | I40: 109.151
A41: Proceeds from Sale of Stock | B41: 0 | C41: 0 | D41: 0 | E41: 0 | F41: 0 | G41: 942.529 | H41: 107.5 | I41: 96.48
A42: Proceeds from Stock Options | B42: 596.028 | C42: 745.396 | D42: 218.238 | E42: 86.089 | F42: 0 | G42: 298.829 | H42: 16.897 | I42: 12.671
...

Sheet IS - Estimates
A1: PLTR-USA
A2: Income Statement (M)
B3: Dec '23 | C3: Dec '24 | D3: Mar '25 | E3: Jun '25 | F3: Sep '25 | G3: Dec '25E | H3: Dec '25E | I3: Mar '26E | J3: Jun '26E | K3: Sep '26E | L3: Dec '26E | M3: Dec '26E | N3: Dec '27E
D4: Q1 | E4: Q2 | F4: Q3 | G4: Q4 | I4: Q1 | J4: Q2 | K4: Q3 | L4: Q4
A5: Sales | B5: 2225.01 | C5: 2865.51 | D5: 883.855 | E5: 1003.7 | F5: 1181.09 | G5: 1319.59 | H5: 4405.79 | I5: 1322.72 | J5: 1444.14 | K5: 1622.94 | L5: 1793.87 | M5: 6292.71 | N5: 8734.79
A6: Sharp Consensus | B6: - | C6: - | D6: - | E6: - | F6: - | G6: 1340.32 | H6: - | I6: - | J6: - | K6: - | L6: - | M6: - | N6: -
A7: Guidance (Low) | B7: 2216 | C7: 2805 | D7: 858 | E7: 934 | F7: 1083 | G7: 1327 | H7: 4396 | I7: - | J7: - | K7: - | L7: - | M7: - | N7: -
A8: Guidance (High) | B8: 2220 | C8: 2809 | D8: 862 | E8: 938 | F8: 1087 | G8: 1331 | H8: 4400 | I8: - | J8: - | K8: - | L8: - | M8: - | N8: -
A9: Cost of Sales | B9: 395.11 | C9: 496.925 | D9: 158 | E9: 178 | F9: 191.518 | G9: 219.41 | H9: 773.264 | I9: 224.957 | J9: 243.839 | K9: 270.536 | L9: 295.475 | M9: 1073.1 | N9: 1453.37
A10: Gross Income | B10: 1829.9 | C10: 2368.58 | D10: 725.9 | E10: 825.7 | F10: 989.574 | G10: 1119.43 | H10: 3650.13 | I10: 1094.53 | J10: 1189.99 | K10: 1338.27 | L10: 1490.37 | M10: 5169.42 | N10: 7191.63
A11: EBITDA | B11: 666.1 | C11: 1159.65 | D11: 397.332 | E11: 470.914 | F11: 606.515 | G11: 685.834 | H11: 2145.08 | I11: 667.556 | J11: 740.262 | K11: 828.707 | L11: 899.117 | M11: 3160.11 | N11: 4607.08
A12: Operating Income | B12: 632.776 | C12: 1128.06 | D12: 390.71 | E12: 464.385 | F12: 600.54 | G12: 700.524 | H12: 2145.87 | I12: 637.788 | J12: 706.303 | K12: 819.503 | L12: 920.64 | M12: 3133.46 | N12: 4419.98
A13: Guidance (Low) | B13: 607 | C13: 1054 | D13: 354 | E13: 401 | F13: 493 | G13: 695 | H13: 2151 | I13: - | J13: - | K13: - | L13: - | M13: - | N13: -
A14: Guidance (High) | B14: 611 | C14: 1058 | D14: 358 | E14: 405 | F14: 497 | G14: 699 | H14: 2155 | I14: - | J14: - | K14: - | L14: - | M14: - | N14: -
A15: Interest Income | B15: - | C15: - | D15: 50.44 | E15: 56.2575 | F15: 59.762 | G15: 52.2533 | H15: 218.726 | I15: 49.6667 | J15: 50.3333 | K15: 51 | L15: 51.6667 | M15: 202.667 | N15: 240
A16: Pretax Income | B16: 749.9 | C16: 1306.83 | D16: 438 | E16: 527.218 | F16: 687.792 | G16: 765.14 | H16: 2374.4 | I16: 699.336 | J16: 769.255 | K16: 887.363 | L16: 993.197 | M16: 3413 | N16: 4963.28
A17: Tax Expense | B17: 170.721 | C17: 299.255 | D17: 99.9 | E17: 120.82 | F17: 157.9 | G17: 175.293 | H17: 555.05 | I17: 162.7 | J17: 177.103 | K17: 202.378 | L17: 225.332 | M17: 767.513 | N17: 955.076
A18: Net Income | B18: 571.609 | C18: 1001.85 | D18: 334.405 | E18: 404.551 | F18: 528.709 | G18: 596.697 | H18: 1857.07 | I18: 541.183 | J18: 596.327 | K18: 683.87 | L18: 764.182 | M18: 2671.37 | N18: 3891.86

Sheet CFS - Estimates
A1: PLTR-US
A2: Cash Flow (M)
B3: Dec '23 | C3: Dec '24 | D3: Mar '25 | E3: Jun '25 | F3: Sep '25 | G3: Dec '25E | H3: Dec '25E | I3: Mar '26E | J3: Jun '26E | K3: Sep '26E | L3: Dec '26E | M3: Dec '26E | N3: Dec '27E
D4: Q1 | E4: Q2 | F4: Q3 | G4: Q4 | I4: Q1 | J4: Q2 | K4: Q3 | L4: Q4
A5: Capital Expenditures | B5: 15.107 | C5: 12.634 | D5: 6.184 | E5: 7.634 | F5: 6.792 | G5: 7.68475 | H5: 29.9612 | I5: 9.06806 | J5: 9.54559 | K5: 10.0475 | L5: 10.7073 | M5: 40.6154 | N5: 49.0852
A6: Capitalized Research & Development | B6: 0 | C6: - | D6: - | E6: - | F6: - | G6: - | H6: - | I6: - | J6: - | K6: - | L6: - | M6: - | N6: -
A7: Free Cash Flow | B7: 730.524 | C7: 1249.22 | D7: 370.377 | E7: 568.769 | F7: 539.862 | G7: 594.407 | H7: 2032.32 | I7: 561.33 | J7: 702.11 | K7: 612.211 | L7: 853.901 | M7: 2791.49 | N7: 3831.14
A8: Guidance (Low) | B8: - | C8: 1000 | D8: - | E8: - | F8: - | G8: - | H8: 1900 | I8: - | J8: - | K8: - | L8: - | M8: - | N8: -
A9: Guidance (High) | B9: - | C9: - | D9: - | E9: - | F9: - | G9: - | H9: 2100 | I9: - | J9: - | K9: - | L9: - | M9: - | N9: -
A10: Unlevered Free Cash Flow | B10: - | C10: - | D10: - | E10: - | F10: - | G10: - | H10: - | I10: - | J10: - | K10: - | L10: - | M10: - | N10: -
A11: Cash Flow from Operations | B11: 712.192 | C11: 1153.88 | D11: 310.263 | E11: 539.251 | F11: 507.682 | G11: 569.19 | H11: 2051.53 | I11: 572.824 | J11: 685.409 | K11: 596.353 | L11: 871.374 | M11: 2784.73 | N11: 4386.73
A12: Cash Flow from Investing | B12: -2711.18 | C12: -340.655 | D12: -1390.29 | E12: -617.005 | F12: 181.583 | G12: 7.92267 | H12: -2233.59 | I12: 24.5223 | J12: -10.1365 | K12: -10.5185 | L12: -11.2925 | M12: -45.7792 | N12: -55
A13: Cash Flow from Financing | B13: 218.82 | C13: 463.364 | D13: -28.8985 | E13: 6.425 | F13: 6.4 | G13: -2.5 | H13: -21.5707 | I13: 24.3 | J13: 5 | K13: 3.2 | L13: -2.5 | M13: 15.025 | N13: 30.05

Sheet IS - Quarterly
A1: Palantir Technologies Inc. Class A (PLTR)
A2: $178.40
A5: Palantir Technologies Inc. Class A
A6: PLTR 69608A108 BN78DQ4 NASDAQ Common stock
A7: Source: FactSet Fundamentals
B8: SEP '25 | C8: JUN '25 | D8: MAR '25 | E8: DEC '24 | F8: SEP '24 | G8: JUN '24 | H8: MAR '24 | I8: DEC '23 | J8: SEP '23 | K8: JUN '23
A9: Sales | B9: 1181.092 | C9: 1003.697 | D9: 883.855 | E9: 827.519 | F9: 725.516 | G9: 678.134 | H9: 634.338 | I9: 608.35 | J9: 558.159 | K9: 533.317
A10: Cost of Goods Sold (COGS) incl. D&A | B10: 207.307 | C10: 192.934 | D10: 172.97 | E10: 174.533 | F10: 146.639 | G10: 128.562 | H10: 116.256 | I10: 108.639 | J10: 107.922 | K10: 106.899
A11: COGS excluding D&A | B11: 201.332 | C11: 186.404 | D11: 166.348 | E11: 167.527 | F11: 138.552 | G11: 120.506 | H11: 107.818 | I11: 100.667 | J11: 99.259 | K11: 98.5
A12: Depreciation & Amortization Expense | B12: 5.975 | C12: 6.53 | D12: 6.622 | E12: 7.006 | F12: 8.087 | G12: 8.056 | H12: 8.438 | I12: 7.972 | J12: 8.663 | K12: 8.399
A13: Depreciation | B13: 4.8 | C13: 5.4 | D13: 5.5 | E13: 5.587 | F13: 6.1 | G13: 8.056 | H13: 8.438 | I13: 7.972 | J13: 8.663 | K13: 8.399
A14: Amortization of Intangibles | B14: 1.175 | C14: 1.13 | D14: 1.122 | E14: 1.419 | F14: 1.987 | G14: 0 | H14: 0 | I14: 0 | J14: 0 | K14: 0
A15: Gross Income | B15: 973.785 | C15: 810.763 | D15: 710.885 | E15: 652.986 | F15: 578.877 | G15: 549.572 | H15: 518.082 | I15: 499.711 | J15: 450.237 | K15: 426.418
A16: SG&A Expense | B16: 580.529 | C16: 541.446 | D16: 534.837 | E16: 641.943 | F16: 465.737 | G16: 444.233 | H16: 437.201 | I16: 433.917 | J16: 410.254 | K16: 416.344
A17: Research & Development | B17: 144.191 | C17: 135.043 | D17: 134.889 | E17: 171.502 | F17: 117.555 | G17: 108.781 | H17: 110.04 | I17: 109.283 | J17: 105.708 | K17: 99.533
A18: Other SG&A | B18: 436.338 | C18: 406.403 | D18: 399.948 | E18: 470.441 | F18: 348.182 | G18: 335.452 | H18: 327.161 | I18: 324.634 | J18: 304.546 | K18: 316.811
A19: EBIT (Operating Income) | B19: 393.256 | C19: 269.317 | D19: 176.048 | E19: 11.043 | F19: 113.14 | G19: 105.339 | H19: 80.881 | I19: 65.794 | J19: 39.983 | K19: 10.074
A20: Nonoperating Income - Net | B20: 93.245 | C20: 50.251 | D20: 57.968 | E20: 57.295 | F20: 49.41 | G20: 42.02 | H20: 40.745 | I20: 39.489 | J20: 41.428 | K20: 21.886
... A33: Net Income available to Common | B33: 475.599 | C33: 326.727 | D33: 214.031 | E33: 79.009 | F33: 143.525 | G33: 134.126 | H33: 105.53 | I33: 93.391 | J33: 71.505 | K33: 28.127
A34: Per Share
A35: EPS (recurring) | B35: 0.186615 | C35: 0.124041 | D35: 0.086775 | E35: 0.027872 | F35: 0.05989 | G35: 0.057459 | H35: 0.047148 | I35: 0.039284 | J35: 0.030958 | K35: 0.012531
A36: EPS (basic) | B36: 0.2001 | C36: 0.1381 | D36: 0.0911 | E36: 0.0343 | F36: 0.0638 | G36: 0.0601 | H36: 0.0477 | I36: 0.0427 | J36: 0.0331 | K36: 0.0132
A37: Basic Shares Outstanding | B37: 2377.167 | C37: 2365.196 | D37: 2348.679 | E37: 2304.883 | F37: 2250.032 | G37: 2231.592 | H37: 2213.545 | I37: 2187.214 | J37: 2162.53 | K37: 2131.224
A38: Total Shares Outstanding | B38: 2383.314 | C38: 2371.847 | D38: 2359.663 | E38: 2338.795 | F38: 2269.809 | G38: 2237.939 | H38: 2226.963 | I38: 2200.128 | J38: 2175.241 | K38: 2149.98
A39: EPS (diluted) | B39: 0.185 | C39: 0.1275 | D39: 0.0838 | E39: 0.0312 | F39: 0.0584 | G39: 0.0556 | H39: 0.044 | I39: 0.0396 | J39: 0.0308 | K39: 0.0124
A40: Diluted Shares Outstanding | B40: 2571.057 | C40: 2562.912 | D40: 2552.818 | E40: 2528.279 | F40: 2459.589 | G40: 2414.696 | H40: 2400.107 | I40: 2357.742 | J40: 2325.6 | K40: 2278.155
A41: Total Shares Outstanding | B41: 2383.314 | C41: 2371.847 | D41: 2359.663 | E41: 2338.795 | F41: 2269.809 | G41: 2237.939 | H41: 2226.963 | I41: 2200.128 | J41: 2175.241 | K41: 2149.98
A42: Earnings Persistence | B42: 53.516 | C42: 42.537 | D42: 48.515 | E42: 34.01 | F42: 26.542 | G42: 23.322 | H42: 2.085 | I42: 0 | J42: 0 | K42: 0
A43: EBITDA
A44: EBITDA | B44: 399.231 | C44: 275.847 | D44: 182.67 | E44: 18.049 | F44: 121.227 | G44: 113.395 | H44: 89.319 | I44: 73.766 | J44: 48.646 | K44: 18.473
A45: EBIT | B45: 393.256 | C45: 269.317 | D45: 176.048 | E45: 11.043 | F45: 113.14 | G45: 105.339 | H45: 80.881 | I45: 65.794 | J45: 39.983 | K45: 10.074
A46: Depreciation & Amortization Expense | B46: 5.975 | C46: 6.53 | D46: 6.622 | E46: 7.006 | F46: 8.087 | G46: 8.056 | H46: 8.438 | I46: 7.972 | J46: 8.663 | K46: 8.399
A47: All figures in millions of U.S. Dollar except per share items.

Sheet CFS - Quarterly
A1: Palantir Technologies Inc. Class A (PLTR)
A2: $178.40
A5: Palantir Technologies Inc. Class A
A6: PLTR 69608A108 BN78DQ4 NASDAQ Common stock
A7: Source: FactSet Fundamentals
B8: SEP '25 | C8: JUN '25 | D8: MAR '25 | E8: DEC '24 | F8: SEP '24 | G8: JUN '24 | H8: MAR '24 | I8: DEC '23 | J8: SEP '23 | K8: JUN '23
A9: Operating Activities
A10: Net Income / Starting Line | B10: 476.748 | C10: 328.572 | D10: 217.717 | E10: 76.936 | F10: 149.341 | G10: 135.57 | H10: 106.071 | I10: 96.913 | J10: 73.439 | K10: 27.872
A11: Depreciation, Depletion & Amortization | B11: 5.975 | C11: 6.53 | D11: 6.622 | E11: 7.006 | F11: 8.087 | G11: 8.056 | H11: 8.438 | I11: 7.972 | J11: 8.663 | K11: 8.399
A12: Depreciation and Depletion | B12: 4.8 | C12: 5.4 | D12: 5.5 | E12: 5.587 | F12: 1.706 | G12: 8.056 | H12: 8.438 | I12: 7.972 | J12: 8.663 | K12: 8.399
A13: Amortization of Intangible Assets | B13: 1.175 | C13: 1.13 | D13: 1.122 | E13: 1.419
A14: Deferred Taxes & Investment Tax Credit | B14: 0 | C14: 0 | D14: 0 | E14: 0 | F14: 0 | G14: 0 | H14: 0 | I14: -4.806 | J14: 0 | K14: 0
A15: Deferred Taxes | B15: 0 | C15: 0 | D15: 0 | E15: 0 | F15: 0 | G15: 0 | H15: 0 | I15: -4.806 | J15: 0 | K15: 0
A16: Other Funds | B16: 159.463 | C16: 164.705 | D16: 152.245 | E16: 272.229 | F16: 179.904 | G16: 140.634 | H16: 131.69 | I16: 118.289 | J16: 117.001 | K16: 112.854
A17: Funds from Operations | B17: 642.186 | C17: 499.807 | D17: 376.584 | E17: 356.171 | F17: 337.332 | G17: 284.26 | H17: 246.199 | I17: 218.368 | J17: 199.103 | K17: 138.289
A18: Changes in Working Capital | B18: -134.522 | C18: 39.444 | D18: -66.321 | E18: 104.156 | F18: 82.44 | G18: -140.073 | H18: -116.62 | I18: 82.804 | J18: -65.66 | K18: -48.097
A19: Receivables | B19: -259.476 | C19: -28.542 | D19: -134.959 | E19: 100.542 | F19: -13.388 | G19: -176.427 | H19: -121.884 | I19: 53.593 | J19: -46.089 | K19: -113.035
A20: Accounts Payable | B20: 42.38 | C20: 25.807 | D20: 22.395 | E20: -26.551 | F20: -45.662 | G20: 29.563 | H20: 23.809 | I20: 0.555 | J20: 6.67 | K20: 0.864
A21: Other Accruals | E21: 73.485 | F21: 72.697 | G21: -11.443 | H21: -19.105 | I21: 50.343 | J21: -11.228 | K21: 9.509
A22: Other Assets/Liabilities | B22: 82.574 | C22: 42.179 | D22: 46.243 | E22: -43.32 | F22: 68.793 | G22: 18.234 | H22: 0.56 | I22: -21.687 | J22: -15.013 | K22: 54.565
A23: Net Operating Cash Flow | B23: 507.664 | C23: 539.251 | D23: 310.263 | E23: 460.327 | F23: 419.772 | G23: 144.187 | H23: 129.579 | I23: 301.172 | J23: 133.443 | K23: 90.192
A24: Investing Activities
A25: Capital Expenditures | B25: -6.792 | C25: -7.634 | D25: -6.184 | E25: -3.106 | F25: -3.985 | G25: -2.879 | H25: -2.664 | I25: -4.86 | J25: -1.565 | K25: -3.934
A26: Capital Expenditures (Fixed Assets) | B26: -6.792 | C26: -7.634 | D26: -6.184 | E26: -3.106 | F26: -3.985 | G26: -2.879 | H26: -2.664 | I26: -4.86 | J26: -1.565 | K26: -3.934
A27: Purchase/Sale of Investments | B27: 192.283 | C27: -569.376 | D27: -1354.093 | E27: 644.915 | F27: -316.741 | G27: -141.999 | H27: -508.581 | I27: -564.366 | J27: -194.699 | K27: -387.165
A28: Purchase of Investments | B28: 3515.282 | C28: 871.511 | D28: 1704.72 | E28: 1977.214 | F28: 1634.584 | G28: 523.788 | H28: 1260.327 | I28: 844.736 | J28: 1854.731 | K28: 626.572
A29: Sale/Maturity of Investments | B29: 3707.565 | C29: 302.135 | D29: 350.627 | E29: 2622.129 | F29: 1317.843 | G29: 381.789 | H29: 751.746 | I29: 280.37 | J29: 1660.032 | K29: 239.407
A30: Other Funds | B30: -3.924 | C30: -40 | D30: -30 | E30: -1.615 | F30: 0 | G30: -4 | H30: 0 | I30: 0 | J30: 0 | K30: 0
A31: Other Uses | B31: -3.924 | C31: -40 | D31: -30 | E31: -1.615 | F31: 0 | G31: -4 | H31: 0 | I31: 0 | J31: 0 | K31: 0
A32: Net Investing Cash Flow | B32: 181.567 | C32: -617.01 | D32: -1390.277 | E32: 640.194 | F32: -320.726 | G32: -148.878 | H32: -511.245 | I32: -569.226 | J32: -196.264 | K32: -391.099
A33: Financing Activities
A34: Change in Capital Stock | B34: 6.443 | C34: 10.021 | D34: 48.586 | E34: 456.591 | F34: 151.438 | G34: -1.669 | H34: 74.84 | I34: 51.409 | J34: 50.556 | K34: 90.349
A35: Repurchase of Common & Preferred Stk. | B35: -19.195 | C35: -18.596 | D35: -17.998 | E35: -18.598 | F35: -18.899 | G35: -17.699 | H35: -9 | I35: 0 | J35: 0 | K35: 0
A36: Sale of Common & Preferred Stock | B36: 25.638 | C36: 28.617 | D36: 66.584 | E36: 475.189 | F36: 170.337 | G36: 16.03 | H36: 83.84 | I36: 51.409 | J36: 50.556 | K36: 90.349
A37: Proceeds from Stock Options | B37: 25.638 | C37: 28.617 | D37: 66.584 | E37: 475.189 | F37: 170.337 | G37: 16.03 | H37: 83.84 | I37: 51.409 | J37: 50.556 | K37: 90.349
A38: Other Funds | B38: -0.008 | C38: -3.571 | D38: -77.483 | E38: -217.927 | F38: -0.011 | G38: -0.306 | H38: 0.408 | I38: -0.177 | J38: 0.384 | K38: 0.335
A39: Other Uses | B39: 0 | C39: -3.544 | D39: -77.573 | E39: -218.28 | F39: 0 | G39: 0 | H39: 0 | I39: 0 | J39: 0 | K39: 0
A40: Other Sources | B40: -0.008 | C40: -0.027 | D40: 0.09 | E40: 0.353 | F40: -0.011 | G40: -0.306 | H40: 0.408 | I40: -0.177 | J40: 0.384 | K40: 0.335
A41: Net Financing Cash Flow | B41: 6.435 | C41: 6.45 | D41: -28.897 | E41: 238.664 | F41: 151.427 | G41: -1.975 | H41: 75.248 | I41: 51.232 | J41: 50.94 | K41: 90.684
A42: All Activities
...
